<!-- ---
layout: cnblog_post
title:  "error"
permalink: '/misc/error'
date:   2018-12-23 07:34:39
categories: misc
--- -->

未知错误如何保证一定能打印到error_log
如何快速定位来自某一客户端请求引起的错误


任何访问引起的异常，应该统一打印到一处，并附带trace_back



本地Python manager runserver 请求处理逻辑中出现异常，没有在middleware中捕获

log打印情况：
①console: 访问log `ERROR:[Dec 23 15:23:04]:@/Users/mike/.pyenv/versions/3.6.5/envs/official_accounts/lib/python3.6/site-packages/django/core/servers/basehttp.py:log_message,124: "GET / HTTP/1.1" 500 95595
`
②out：trace_back, 访问log, 访问log

```
ERROR:[Dec 23 15:23:04]:@/Users/mike/.pyenv/versions/3.6.5/envs/official_accounts/lib/python3.6/site-packages/django/utils/log.py:log_response,228: Internal Server Error: /
Traceback (most recent call last):
  File "/Users/mike/.pyenv/versions/3.6.5/envs/official_accounts/lib/python3.6/site-packages/django/core/handlers/exception.py", line 34, in inner
    response = get_response(request)
  File "/Users/mike/.pyenv/versions/3.6.5/envs/official_accounts/lib/python3.6/site-packages/django/core/handlers/base.py", line 126, in _get_response
    response = self.process_exception_by_middleware(e, request)
  File "/Users/mike/.pyenv/versions/3.6.5/envs/official_accounts/lib/python3.6/site-packages/django/core/handlers/base.py", line 124, in _get_response
    response = wrapped_callback(request, *callback_args, **callback_kwargs)
  File "/Users/mike/.pyenv/versions/3.6.5/envs/official_accounts/lib/python3.6/site-packages/django/views/decorators/csrf.py", line 54, in wrapped_view
    return view_func(*args, **kwargs)
  File "/Users/mike/.pyenv/versions/3.6.5/envs/official_accounts/lib/python3.6/site-packages/django/views/generic/base.py", line 68, in view
    return self.dispatch(request, *args, **kwargs)
  File "/Users/mike/.pyenv/versions/3.6.5/envs/official_accounts/lib/python3.6/site-packages/rest_framework/views.py", line 495, in dispatch
    response = self.handle_exception(exc)
  File "/Users/mike/.pyenv/versions/3.6.5/envs/official_accounts/lib/python3.6/site-packages/rest_framework/views.py", line 455, in handle_exception
    self.raise_uncaught_exception(exc)
  File "/Users/mike/.pyenv/versions/3.6.5/envs/official_accounts/lib/python3.6/site-packages/rest_framework/views.py", line 492, in dispatch
    response = handler(request, *args, **kwargs)
  File "/Users/mike/.pyenv/versions/3.6.5/envs/official_accounts/lib/python3.6/site-packages/rest_framework/generics.py", line 210, in get
    return self.retrieve(request, *args, **kwargs)
  File "/Users/mike/Documents/xuetang/归档/we/gongzhong/views.py", line 24, in retrieve
    raise Exception('00000000000000000000000')
Exception: 00000000000000000000000
ERROR:[Dec 23 15:23:04]:@/Users/mike/.pyenv/versions/3.6.5/envs/official_accounts/lib/python3.6/site-packages/django/core/servers/basehttp.py:log_message,124: "GET / HTTP/1.1" 500 95595
ERROR:[Dec 23 15:23:04]:@/Users/mike/.pyenv/versions/3.6.5/envs/official_accounts/lib/python3.6/site-packages/django/core/servers/basehttp.py:log_message,124: "GET / HTTP/1.1" 500 95595
```


```
# django/core/servers/basehttp.py

logger = logging.getLogger('django.server')

124: log_message方法中的logger
```

```
# django/utils/log.py

12: request_logger = logging.getLogger('django.request')

228: log_response方法 222行调用

```

有middleware处理： 出现异常 ---> middleware处理 ---> 正确返回
没有            ： 出现异常 ---> process_exception_by_middleware直接raise

```
def process_exception_by_middleware(self, exception, request):
    """
    Pass the exception to the exception middleware. If no middleware
    return a response for this exception, raise it.
    """
    for middleware_method in self._exception_middleware:
        response = middleware_method(request, exception)
        if response:
            return response
    raise
```


raise 之后由 django.core.handlers.exceptions.py 中的下面方法捕获

```
def convert_exception_to_response(get_response):
    @wraps(get_response)
    def inner(request):
        try:
            response = get_response(request)
        except Exception as exc:
            response = response_for_exception(request, exc)
        return response
    return inner
```

response_for_exception 方法继续处理错误:

```
def response_for_exception(request, exc):
    if isinstance(exc, Http404):
        # ....
    elif isinstance(exc, PermissionDenied):
        # ...
    elif isinstance(exc, MultiPartParserError):
        # ...
    elif isinstance(exc, SuspiciousOperation):
        # ...
    elif isinstance(exc, SystemExit):
        raise
    else:
        signals.got_request_exception.send(sender=None, request=request)
        # 生成相应的response => 500
        response = handle_uncaught_exception(request, get_resolver(get_urlconf()), sys.exc_info())
        #  打印访问log
        log_response(
            '%s: %s', response.reason_phrase, request.path,
            response=response,
            request=request,
            exc_info=sys.exc_info(),
        ) 

        # Force a TemplateResponse to be rendered.
        if not getattr(response, 'is_rendered', True) and callable(getattr(response, 'render', None)):
            response = response.render()

        return response
```

sys.exc_info()其实是一个元组: ()
追踪Python官方logger如何打印sys 查看系统logger的
self._log(ERROR, msg, args, **kwargs)

def _log(self, level, msg, args, exc_info=None, extra=None, stack_info=False):
    # ...
    record = self.makeRecord(self.name, level, fn, lno, msg, args,
                                 exc_info, func, extra, sinfo)
    self.handle(record)

def makeRecord(self, name, level, fn, lno, msg, args, exc_info,
                   func=None, extra=None, sinfo=None):
    rv = _logRecordFactory(name, level, fn, lno, msg, args, exc_info, func,
                             sinfo)
    # ...
    return rv

_logRecordFactory = LogRecord

class LogRecord:
    # ...
    def format(self, record):
        # ...
        s = self.formatMessage(record)
        if record.exc_info:
            # Cache the traceback text to avoid converting it multiple times
            # (it's constant anyway)
            if not record.exc_text:
                record.exc_text = self.formatException(record.exc_info)
        if record.exc_text:
            if s[-1:] != "\n":
                s = s + "\n"
            s = s + record.exc_text
        return s


    def formatException(self, ei):
        sio = io.StringIO()
        tb = ei[2]
        # ...
        traceback.print_exception(ei[0], ei[1], tb, None, sio)
        s = sio.getvalue()
        sio.close()
        if s[-1:] == "\n":
            s = s[:-1]
        return s


目标：
系统和子系统的异常：打印到console和file、sentry
异常处理middleware： 给客户端合适的信息，状态码，



--------------------------------

django.request对应了logger 只调用了WARNING(4xx) ERROR(5xx), 在django/core/handlers/exception.py:handle_uncaught_exception,118  打印traceback<br/>
访问日志 django.server 在django/core/servers/basehttp.py:log_message,124: 打印<br/>

middleware 捕获后 无法到达django/core/handlers/exception.py: 
---所有接口和middleware需要补充：如果是4xx warning 如果是 5xx error

logger.exception 会自动打印 ERROR + exec_info
getLogger(__name__) 如果__name__ 没有在logger中专门设置，会使用`''`设置的logger



任何logger.error到达django.logger 配置 'ERROR' (在sentry这个handler配置)，
并且对应的logger启用了sentry这个handler都会 发送

from raven.contrib.django.raven_compat.models import client
主动发送，client.captureException() 会收集当前代码的exec_info,发送一次

